Workbook

Sheet 참조
A1: 해당
A2: N/A

Sheet 업종코드
A1: 업종코드 | B1: 업태명 | C1: 중분류 | D1: 세분류 | E1: 세세분류 | F1: 적용기준내용 | G1: 단순경비율(일반율) | H1: 단순경비율(초과율) | I1: 기준경비율(일반율)
A2: 011000 | B2: 농업, 임업 및 어업 | C2: 농업 | D2: 곡물 및 기타 식량작물 재배업 | E2: 곡물 및 기타 식량작물 재배업 | F2: ◦곡물작물, 식량용 뿌리작물, 콩과 작물 및 기타식량작물을 재배하는 산업활동을 말한다. <예 시> ·벼, 보리, 밀, 수수 재배 ·감자, 고구마 재배 ·메밀 재배 ·옥수수, 콩, 녹두 재배 <제 외> ·작물의 종묘 생산(011003) ·시설작물 재배(011007~011009) ·사료용 작물 재배(011006) ·과실, 견과, 음료용 또는 향신용 작물 재배(011004,011005) | G2: 0 | H2: 0 | I2: 0
A3: 011001 | B3: 농업, 임업 및 어업 | C3: 농업 | D3: 채소, 화훼작물 및 종묘 재배업 | E3: 채소작물 재배업 | F3: ◦노지에서 각종 채소작물을 재배하는 산업활동을 말한다. 노지에서 깻잎 등과 같이 채소로 사용하기 위하여 각종 작물을 재배하는 경우에도 여기에 분류된다. <예 시> ·풋마늘, 마늘 및 풋고추 재배 ·파 및 양파 재배 ·아스파라거스 재배 ·참외, 수박 및 멜론, 딸기, 토마토 등 과일채소 재배 ·잎채소 재배 <제 외> ·채소작물 종자 및 묘목 생산(011003) ·커피, 코코아, 차, 겨자, 붉은 고추 등의 음료용 또는 향신용 작물 재배(011005) ·콩나물, 버섯 및 기타 채소작물의 시설재배(011007~011009) | G3: 93.5 | H3: 0 | I3: 9.7
A4: 011002 | B4: 농업, 임업 및 어업 | C4: 농업 | D4: 채소, 화훼작물 및 종묘 재배업 | E4: 화훼작물 재배업 | F4: ◦노지에서 화초, 잔디, 관상수 등과 같은 장식, 관상, 조원 및 조경용의 수목◦꽃◦풀 등을 재배하는 산업활동을 말한다. <예 시> ·정원수 재배 ·조원용 풀 재배 ·절화용 화초 재배 ·분재 재배 <제 외> ·화훼작물의 종자 및 묘목 생산(011003) ·화훼작물의 시설재배(011008) ·공원에 화훼작물 식재 및 관리 활동(749303) | G4: 93.5 | H4: 0 | I4: 5.4
A5: 011003 | B5: 농업, 임업 및 어업 | C5: 농업 | D5: 채소, 화훼작물 및 종묘 재배업 | E5: 종자 및 묘목 생산업 | F5: ◦노지 또는 시설에서 각종 농작물의 종자, 버섯 종균, 묘목 등을 생산하는 산업활동을 말한다. <예 시> ·채소, 화초, 과수 종자 생산 ·채소, 화초, 과수 묘목 생산 ·버섯 종균 생산 ·접수 및 삽수 묘목 생산 ·화초 종근 생산 ·벼 모판 생산 <제 외> ·육림용 종자 및 묘목 생산(020100) ·종균 없는 버섯재배용 배지 혼합·발효생산(369908) ·종균 없는 버섯재배용 배지 단순 혼합 생산·판매(G) ·공원에 화훼작물 식재 및 관리 활동(749303) | G5: 93.5 | H5: 0 | I5: 5.9
A6: 011004 | B6: 농업, 임업 및 어업 | C6: 농업 | D6: 과실, 음료용 및 향신용 작물 재배업 | E6: 과실작물 재배업 | F6: ◦노지에서 견과(땅콩 제외)를 포함한 각종 과실작물을 재배하는 산업활동을 말한다. <예 시> ·밤, 호두 및 대추 재배 ·복숭아, 포도 및 감귤 재배 ·바나나 재배 ·키위 및 망고스틴 재배 ·무화과 재배 <제 외> ·호프 재배(011006) ·낙화생(땅콩) 재배(011006) ·유지(기름 추출용) 작물 재배(011006) ·멜론, 수박, 토마토 및 기타 과일채소 노지재배(011001) | G6: 93.5 | H6: 0 | I6: 5.8
A7: 011005 | B7: 농업, 임업 및 어업 | C7: 농업 | D7: 과실, 음료용 및 향신용 작물 재배업 | E7: 음료용 및 향신용 작물 재배업 | F7: ◦노지에서 음료용 또는 향신용 작물을 재배하는 산업활동을 말한다. <예 시> ·고추(풋고추 제외) 재배 ·생강 재배 ·정향 재배 ·녹차용 작물 재배 ·커피 재배 ·코코아 재배 <제 외> ·커피 가공(154901), 차류 가공(154905) ·향신료 가공(154501,154509) | G7: 93.5 | H7: 0 | I7: 9
A8: 011006 | B8: 농업, 임업 및 어업 | C8: 농업 | D8: 기타 작물 재배업 | E8: 기타 작물 재배업 | F8: ◦노지에서 약용작물, 사료작물, 기름추출용 작물 및 공업용 원료작물 등 달리 분류되지 않은 기타 작물을 재배하는 산업활동을 말한다. <예 시> ·인삼 재배 ·호프 재배 ·섬유작물 재배 ·비 및 솔 제조용 작물 재배 ·유지작물 재배 ·조물재료용 작물 재배 ·낙화생(땅콩) 재배 ·잎담배 재배 <제 외> ·곡물 및 기타 식량작물 재배(011000) ·음료용 및 향신용 작물 재배(011005) ·작물 배양 재배(011009) ·식용과 사료용으로 모두 가능한 작물은 해당 작물 재배업으로 분류 | G8: 93.5 | H8: 0 | I8: 11.1
A9: 011007 | B9: 농업, 임업 및 어업 | C9: 농업 | D9: 시설작물 재배업 | E9: 기타 시설작물 재배업 | F9: ◦콩나물을 재배하는 산업활동을 말한다. | G9: 93.5 | H9: 0 | I9: 4.4
A10: 011008 | B10: 농업, 임업 및 어업 | C10: 농업 | D10: 시설작물 재배업 | E10: 채소, 화훼 및 과실작물 시설 재배업 | F10: ◦시설 내에서 채소, 화훼 및 과실작물을 재배하는 산업활동을 말한다. <제 외> ·음료용 및 향신용, 공예용 작물 시설 재배(011009) | G10: 93.5 | H10: 0 | I10: 14.4
A11: 011009 | B11: 농업, 임업 및 어업 | C11: 농업 | D11: 시설작물 재배업 | E11: 기타 시설작물 재배업 | F11: ◦콩나물, 채소, 화훼 및 과실작물 이외의 각종 작물을 시설 재배하는 산업활동을 말한다. <예 시> ··버섯 재배 ·작물 배양 재배 ·음료용 작물 시설재배 ·공예작물 시설재배 ·향신용 작물 시설재배 <제 외> ·화훼작물 시설 재배(011008) ·노지 및 시설 내에서 종묘 생산(011003) ·콩나물 재배(011007) | G11: 93.5 | H11: 0 | I11: 9.4
A12: 012101 | B12: 농업, 임업 및 어업 | C12: 농업 | D12: 소 사육업 | E12: 육우 사육업 | F12: ◦쇠고기를 생산하기 위하여 육우를 사육하는 산업활동을 말한다. 젖소 이외 기타 용도의 소 사육업도 포함한다. | G12: 97.2 | H12: 0 | I12: 7.8
A13: 012102 | B13: 농업, 임업 및 어업 | C13: 농업 | D13: 기타 축산업 | E13: 말 및 양 사육업 | F13: ◦각종 용도의 말, 양 및 염소를 사육하는 산업활동을 말한다. <예 시> ·양 사육 ·양모 생산 ·당나귀 사육 ·양젖 생산 ·말 사육 <제 외> ·수수료 또는 계약에 의한 양털 깎기 및 사육장 서비스 활동(014300) ·도축활동에 관련된 양모 생산(151101) ·경마장에서 경주마를 사육관리하는 경우(924202) | G13: 91.8 | H13: 0 | I13: 11.4
... A1542: 950002 | B1542: 보건업 및 사회복지 서비스업 | C1542: 사회복지 서비스업 | D1542: 보육시설 운영업 | E1542: 보육시설 운영업 | F1542: ◦보호자로부터 위탁을 받아 유아 및 취학 전 어린이를 보육하는 산업활동을 말한다.(「영유아보육법」 제13조에 따라 설치 및 인가된 경우 제외) <예 시> ·놀이방 ·직장 보육시설 ·탁아시설 <제 외> ·아동 교육기관(851100) *유아 및 취학 전 어린이 보육(인가된 경우)(→872100) | G1542: 86.6 | H1542: 0 | I1542: 17.5

Sheet 프리
B1: 노랑셀만입력 | F1: 검정셀은수식 | H1: 입력하지마시오
A2: 확인사항 | C2: 기장의무 | D2: 유형체크 | E2: 금액 | F2: 업종코드 | H2: 체크!!!
A3: 장부유형확인 | C3: 복식부기의무자 | H3: =IF(D3="해당","세무사보고","Pass")
C4: 복식i(사전성실) | H4: =IF(D4="해당","세무사보고","Pass")
B5: 6000이상 | C5: 간장복식 | D5: N/A | H5: =IF(D5="해당","세무사보고","Pass")
C6: 간편장부대상자 | D6: 해당 | H6: =IF(D6="해당","세무사보고","Pass")
C7: 간편i(사전성실) | H7: =IF(D7="해당","세무사보고","Pass")
C8: E유형 | H8: =IF(D8="해당","세무사보고","Pass")
C9: 단순율(G등) | H9: =IF(D9="해당","세무사보고","Pass")
A10: 소득종류확인 | B10: 사업 | C10: 사업자등록 | H10: =IF(D10="해당","부가세출력","Pass")
B11: 사업 | C11: 프리랜서 | D11: 해당 | G11: =VLOOKUP(F11,업종코드!$A$1:$I$1542,6,FALSE) | H11: =IF(D11="해당","Pass","Pass") | J11: 수입금액 | K11: 적정소득율 | L11: 수임동의 | M11: 접수방법
B12: 근로 | D12: N/A | E12: 17475420 | H12: =IF(D12="해당","세무사보고","Pass") | L12: 동의 | M12: 홈택스
B13: 연금 | H13: =IF(D13="해당","세무사보고","Pass") | L13: 동의 | M13: 홈택스
B14: 기타 | D14: N/A | E14: 0 | H14: =IF(D14="해당","세무사보고","Pass")
B15: 금융 | H15: =IF(D15="해당","세무사보고","Pass")
B16: 주택임대 | E16: 0 | H16: =IF(D16="해당","세무사보고","Pass") | J16: 50000000 | K16: 0.3247 | L16: 동의 | M16: 홈택스
A17: 수입금액(사업자) | C17: =E10 | D17: 수입금액(프리) | F17: =E11 | H17: =IF(D17="해당","세무사보고","Pass") | J17: 60000000 | K17: 0.3319
A18: 제출자료경비 | C18: =C19+C20 | D18: 필요경비 | F18: =F19+F20 | J18: 65000000 | K18: 0.3814
B19: 신용카드 | E19: 신용카드 | J19: 75000000 | K19: 0.4251
B20: 기타비용 | E20: 기타비용 | J20: 100000000 | K20: 0.4889
A21: 실질INCOME | C21: =C17-C18 | F21: =F17-F18 | J21: 150000000 | K21: 0.5476
A22: GAP | F22: =F21-F23 | H22: =IF(F22>=50000000,"세무사보고","Pass") | J22: 200000000 | K22: 0.5836
A23: target소득금액 | D23: 소득율 | F23: =F17*E27 | H23: =IF(F23>=50000000,"세무사보고","Pass")
A24: 업종단순율 | E24: =VLOOKUP(F11,업종코드!$A$1:$I$1532,7,FALSE)
A25: 업종소득율 | E25: =1-E24*0.01
A26: 수입구간별 | E26: =VLOOKUP(E11,$J$11:$K$22,2,TRUE)
A27: 적용 | E27: =IF(E11<50000000,MIN(E25,E26),MAX(E25,E26))
A28: 필요경비 | C28: =C17-C23 | D28: 필요경비 | F28: =F17-F23
A29: 당기매입 | H29: =IF(F29>=120000000,"Error","Pass")
A30: 급여 | D30: 급여 | H30: =IF(F30>=120000000,"Error","Pass") | J30: 8894112 | K30: 7917014 | L30: 16366295
A31: 제세공과금 | D31: 제세공과금 | J31: 37570000 | K31: 36500000 | L31: 71686398
A32: 급여 | D32: 급여 | J32: =J30/J31 | K32: =K30/K31 | L32: =L30/L31
A33: 제세공과금 | D33: 제세공과금
A34: 임차료 | D34: 임차료
A35: 지급이자 | D35: 지급이자
A36: 접대비 | D36: 접대비 | H36: =IF(F36>=120000000,"Error","Pass")
A37: 기부금 | D37: 기부금
A38: 감가상각비 | D38: 감가상각비 | H38: =IF(F38>0,"차량확인","Pass")
A39: 차량유지비 | D39: 차량유지비 | H39: =IF(F39>0,"차량확인","Pass")
A40: 지급수수료 | D40: 지급수수료
...

Sheet 프리+프리
B1: 노랑셀만입력 | F1: 검정셀은수식 | H1: 입력하지마시오
A2: 확인사항 | C2: 기장의무 | D2: 유형체크 | E2: 금액 | F2: 업종코드 | G2: 합계 | H2: 체크!!!
A3: 장부유형확인 | C3: 복식부기의무자 | H3: =IF(D3="해당","세무사보고","Pass")
C4: 복식i(사전성실) | H4: =IF(D4="해당","세무사보고","Pass")
B5: 6000이상 | C5: 간장복식 | D5: N/A | H5: =IF(D5="해당","세무사보고","Pass")
C6: 간편장부대상자 | D6: 해당 | H6: =IF(D6="해당","세무사보고","Pass")
C7: 간편i(사전성실) | D7: N/A | H7: =IF(D7="해당","세무사보고","Pass")
C8: E유형 | H8: =IF(D8="해당","세무사보고","Pass")
C9: 단순율(G등) | H9: =IF(D9="해당","세무사보고","Pass")
A10: 소득종류확인 | B10: 사업 | C10: 프리랜서 | D10: 해당 | G10: =VLOOKUP(F10,업종코드!$A$1:$I$1542,4,FALSE) | H10: =IF(D11="해당","종류확인","Pass")
B11: 사업 | C11: 프리랜서 | D11: 해당 | G11: =VLOOKUP(F11,업종코드!$A$1:$I$1542,6,FALSE) | H11: =IF(D10="해당","종류확인","Pass") | J11: 수입금액 | K11: 적정소득율 | L11: 수임동의 | M11: 접수방법 | O11: 수입금액 | P11: 적정소득율 | Q11: 수임동의 | R11: 접수방법
B12: 근로 | H12: =IF(D13="해당","세무사보고","Pass") | J12: 0 | K12: 0.2514 | L12: 동의 | M12: 홈택스 | O12: 0 | P12: 0.2714 | Q12: 동의 | R12: 홈택스
B13: 연금 | H13: =IF(#REF!="해당","세무사보고","Pass") | J13: 30000000 | K13: 0.2614 | L13: 동의 | M13: 홈택스 | O13: 30000000 | P13: 0.3148 | Q13: 동의 | R13: 홈택스
B14: 기타 | H14: =IF(D14="해당","세무사보고","Pass") | J14: 35000000 | K14: 0.2857 | O14: 50000000 | P14: 0.3484 | Q14: 동의 | R14: 홈택스
B15: 금융 | H15: =IF(D15="해당","세무사보고","Pass") | J15: 40000000 | K15: 0.3048 | O15: 65000000 | P15: 0.3814
B16: 주택임대 | H16: =IF(D16="해당","세무사보고","Pass") | J16: 50000000 | K16: 0.3247 | L16: 동의 | M16: 홈택스 | O16: 75000000 | P16: 0.4457
A17: 합계액 | E17: =SUM(E10:E16) | J17: 60000000 | K17: 0.3319
A18: 수입금액(사업자) | C18: =E10 | D18: 수입금액(프리) | F18: =E11 | G18: =C18+F18 | J18: 65000000 | K18: 0.3814 | O18: 100000000 | P18: 0.5069
A19: 제출자료경비 | C19: =C20+C21 | D19: 필요경비 | F19: =F20+F21 | G19: =C19+F19 | J19: 75000000 | K19: 0.4251 | O19: 150000000 | P19: 0.5476
B20: 신용카드 | E20: 신용카드 | J20: 100000000 | K20: 0.4889 | O20: 200000000 | P20: 0.5836
B21: 기타비용 | E21: 기타비용 | J21: 150000000 | K21: 0.5476
A22: 실질INCOME | C22: =C18-C19 | F22: =F18-F19 | G22: =C22+F22 | J22: 200000000 | K22: 0.5836
A23: GAP | C23: =C22-C24 | F23: =F22-F24 | H23: =IF(G23>50000000,"세무사보고","Pass")
A24: target소득금액 | C24: =C18*B28 | D24: 소득율 | F24: =F18*E28 | G24: =C24+F24
A25: 업종단순율 | B25: =VLOOKUP(F10,업종코드!$A$1:$I$1542,7,FALSE) | E25: =VLOOKUP(F11,업종코드!$A$1:$I$1542,7,FALSE)
A26: (1)업종소득율 | B26: =1-B25*0.01 | E26: =1-E25*0.01
A27: (2)수입구간별 | B27: =VLOOKUP(E17,$J$11:$K$22,2,TRUE) | E27: =VLOOKUP(E17,$J$11:$K$22,2,TRUE)
A28: Min(1,2) | B28: =IF(E17<50000000,MIN(B26,B27),MAX(B26,B27)) | E28: =IF(E17<50000000,MIN(E26,E27),MAX(E26,E27))
A29: 사업자 필요경비 | C29: =C18-C24 | D29: 프리랜서 필요경비 | F29: =F18-F24
A30: 당기매입액 | D30: 급여
A31: 급여 | D31: 급여
A32: 제세공과금 | D32: 제세공과금
A33: 임차료 | D33: 임차료
A34: 지급이자 | D34: 지급이자
A35: 접대비 | D35: 접대비 | E35: =F35-3530697
A36: 기부금 | D36: 기부금
A37: 감가상각비 | D37: 감가상각비
A38: 차량유지비 | D38: 차량유지비
A39: 지급수수료 | D39: 지급수수료 | E39: =F39-4503540
A40: 소모품비 | D40: 소모품비 | E40: =F40-2245194
...

Sheet 사업자+프리
B1: 노랑셀만입력 | F1: 검정셀은수식 | H1: 입력하지마시오
A2: 확인사항 | C2: 기장의무 | D2: 유형체크 | E2: 금액 | F2: 업종코드 | G2: 합계 | H2: 체크!!!
A3: 장부유형확인 | C3: 복식부기의무자 | H3: =IF(D3="해당","세무사보고","Pass")
C4: 복식i(사전성실) | H4: =IF(D4="해당","세무사보고","Pass")
B5: 6000이상 | C5: 간장복식 | D5: N/A | H5: =IF(D5="해당","세무사보고","Pass")
C6: 간편장부대상자 | D6: 해당 | H6: =IF(D6="해당","세무사보고","Pass")
C7: 간편i(사전성실) | D7: N/A | H7: =IF(D7="해당","세무사보고","Pass")
C8: E유형 | H8: =IF(D8="해당","세무사보고","Pass")
C9: 단순율(G등) | H9: =IF(D9="해당","세무사보고","Pass")
A10: 소득종류확인 | B10: 사업 | C10: (必)사업자 | D10: 해당 | G10: =VLOOKUP(F10,업종코드!$A$1:$I$1542,4,FALSE) | H10: =IF(D11="해당","종류확인","Pass")
B11: 사업 | C11: 프리랜서 | D11: 해당 | G11: =VLOOKUP(F11,업종코드!$A$1:$I$1542,6,FALSE) | H11: =IF(D10="해당","종류확인","Pass") | J11: 수입금액 | K11: 적정소득율 | L11: 수임동의 | M11: 접수방법 | O11: 수입금액 | P11: 적정소득율 | Q11: 수임동의 | R11: 접수방법
B12: 근로 | H12: =IF(D13="해당","세무사보고","Pass") | J12: 0 | K12: 0.2514 | L12: 동의 | M12: 홈택스 | O12: 0 | P12: 0.2714 | Q12: 동의 | R12: 홈택스
B13: 연금 | H13: =IF(#REF!="해당","세무사보고","Pass") | J13: 30000000 | K13: 0.2614 | L13: 동의 | M13: 홈택스 | O13: 30000000 | P13: 0.3148 | Q13: 동의 | R13: 홈택스
B14: 기타 | H14: =IF(D14="해당","세무사보고","Pass") | J14: 35000000 | K14: 0.2857 | O14: 50000000 | P14: 0.3484 | Q14: 동의 | R14: 홈택스
B15: 금융 | H15: =IF(D15="해당","세무사보고","Pass") | J15: 40000000 | K15: 0.3048 | O15: 65000000 | P15: 0.3814
B16: 주택임대 | H16: =IF(D16="해당","세무사보고","Pass") | J16: 50000000 | K16: 0.3247 | L16: 동의 | M16: 홈택스 | O16: 75000000 | P16: 0.4457
A17: 합계액 | E17: =SUM(E10:E16) | J17: 60000000 | K17: 0.3319
A18: 수입금액(사업자) | C18: =E10 | D18: 수입금액(프리) | F18: =E11 | G18: =C18+F18 | J18: 65000000 | K18: 0.3814 | O18: 100000000 | P18: 0.5069
A19: 제출자료경비 | C19: =C20+C21 | D19: 필요경비 | F19: =F20+F21 | G19: =C19+F19 | J19: 75000000 | K19: 0.4251 | O19: 150000000 | P19: 0.5476
B20: 신용카드 | E20: 신용카드 | J20: 100000000 | K20: 0.4889 | O20: 200000000 | P20: 0.5836
B21: 기타비용 | E21: 기타비용 | J21: 150000000 | K21: 0.5476
A22: 실질INCOME | C22: =C18-C19 | F22: =F18-F19 | G22: =C22+F22 | J22: 200000000 | K22: 0.5836
A23: GAP | C23: =C22-C24 | F23: =F22-F24 | H23: =IF(G23>50000000,"세무사보고","Pass")
A24: target소득금액 | C24: =C18*B28 | D24: 소득율 | F24: =F18*E28 | G24: =C24+F24
A25: 업종단순율 | B25: =VLOOKUP(F10,업종코드!$A$1:$I$1532,7,FALSE) | E25: =VLOOKUP(F11,업종코드!$A$1:$I$1532,7,FALSE)
A26: (1)업종소득율 | B26: =1-B25*0.01 | E26: =1-E25*0.01
A27: (2)수입구간별 | B27: =VLOOKUP(E17,$J$11:$K$22,2,TRUE) | E27: =VLOOKUP(E17,$J$11:$K$22,2,TRUE)
A28: Min(1,2) | B28: =IF(E17<150000000,MIN(B26,B27),MAX(B26,B27)) | E28: =IF(E17<50000000,MIN(E26,E27),MAX(E26,E27))
A29: 사업자 필요경비 | C29: =C18-C24 | D29: 프리랜서 필요경비 | F29: =F18-F24
A30: 당기매입액 | D30: 급여
A31: 급여 | D31: 급여
A32: 제세공과금 | D32: 제세공과금
A33: 임차료 | D33: 임차료
A34: 지급이자 | D34: 지급이자
A35: 접대비 | D35: 접대비
A36: 기부금 | D36: 기부금
A37: 감가상각비 | D37: 감가상각비
A38: 차량유지비 | D38: 차량유지비
A39: 지급수수료 | D39: 지급수수료
A40: 소모품비 | D40: 소모품비
...

Sheet 사업자+사업자
B1: 노랑셀만입력 | F1: 검정셀은수식 | H1: 입력하지마시오
A2: 확인사항 | C2: 기장의무 | D2: 유형체크 | E2: 금액 | F2: 업종코드 | G2: 합계 | H2: 체크!!!
A3: 장부유형확인 | C3: 복식부기의무자 | H3: =IF(D3="해당","세무사보고","Pass")
C4: 복식i(사전성실) | H4: =IF(D4="해당","세무사보고","Pass")
B5: 6000이상 | C5: 간장복식 | D5: N/A | H5: =IF(D5="해당","세무사보고","Pass")
C6: 간편장부대상자 | D6: 해당 | H6: =IF(D6="해당","세무사보고","Pass")
C7: 간편i(사전성실) | D7: N/A | H7: =IF(D7="해당","세무사보고","Pass")
C8: E유형 | H8: =IF(D8="해당","세무사보고","Pass")
C9: 단순율(G등) | H9: =IF(D9="해당","세무사보고","Pass")
A10: 소득종류확인 | B10: 사업 | C10: 사업자등록 | D10: 해당 | G10: =VLOOKUP(F10,업종코드!$A$1:$I$1542,4,FALSE) | H10: =IF(D10="해당","종류확인","Pass")
B11: 사업 | C11: 사업자등록 | D11: 해당 | G11: =VLOOKUP(F11,업종코드!$A$1:$I$1532,4,FALSE) | H11: =IF(D11="해당","종류확인","Pass") | J11: 수입금액 | K11: 적정소득율 | L11: 수임동의 | M11: 접수방법
B12: 근로 | H12: =IF(D12="해당","세무사보고","Pass") | J12: 0 | K12: 0.2514 | L12: 동의 | M12: 홈택스
B13: 연금 | H13: =IF(D13="해당","세무사보고","Pass") | J13: 30000000 | K13: 0.2614 | L13: 동의 | M13: 홈택스
B14: 기타 | H14: =IF(D14="해당","세무사보고","Pass") | J14: 35000000 | K14: 0.2857
B15: 금융 | H15: =IF(D15="해당","세무사보고","Pass") | J15: 40000000 | K15: 0.3048
B16: 주택임대 | H16: =IF(D16="해당","세무사보고","Pass") | J16: 50000000 | K16: 0.3247 | L16: 동의 | M16: 홈택스
A17: 합계 | E17: =SUM(E10:E16)
A18: 수입금액(사업자) | C18: =E10 | D18: 수입금액(사업자) | F18: =E11 | G18: =C18+F18 | J18: 60000000 | K18: 0.3319
A19: 제출자료경비 | C19: =C20+C21 | D19: 필요경비 | F19: =F20+F21 | G19: =C19+F19 | J19: 65000000 | K19: 0.3814
B20: 신용카드 | E20: 신용카드 | J20: 75000000 | K20: 0.4251
B21: 기타비용 | E21: 기타비용 | J21: 100000000 | K21: 0.4889
A22: 실질INCOME | C22: =C18-C19 | F22: =F18-F19 | G22: =C22+F22 | J22: 150000000 | K22: 0.5476
A23: GAP | C23: =C22-C24 | F23: =F22-F24 | H23: =IF(G23>50000000,"세무사보고","Pass") | J23: 200000000 | K23: 0.5836
A24: target소득금액 | C24: =C18*B28 | D24: 소득율 | F24: =F18*E28 | G24: =C24+F24
A25: 업종단순율 | B25: =VLOOKUP(F10,업종코드!$A$1:$I$1532,7,FALSE) | E25: =VLOOKUP(F11,업종코드!$A$1:$I$1532,7,FALSE)
A26: (1)업종소득율 | B26: =1-B25*0.01 | E26: =1-E25*0.01
A27: (2)수입구간별 | B27: =VLOOKUP(E10,$J$11:$K$23,2,TRUE) | E27: =VLOOKUP(E11,$J$11:$K$23,2,TRUE)
A28: Min(1,2) | B28: =IF(E17<150000000,MIN(B26,B27),MAX(B26,B27)) | E28: =IF(E17<150000000,MIN(E26,E27),MAX(E26,E27))
A29: 필요경비 | C29: =C18-C24 | D29: 필요경비 | F29: =F18-F24
A30: 당기매입액 | D30: 급여
A31: 급여 | D31: 급여
A32: 제세공과금 | D32: 제세공과금
A33: 임차료 | D33: 임차료
A34: 지급이자 | D34: 지급이자
A35: 접대비 | D35: 접대비
A36: 기부금 | D36: 기부금
A37: 감가상각비 | D37: 감가상각비 | H37: =IF(G37>0,"차량확인","Pass")
A38: 차량유지비 | D38: 차량유지비 | H38: =IF(G38>0,"차량확인","Pass")
A39: 지급수수료 | D39: 지급수수료
A40: 소모품비 | D40: 소모품비
...
